Workbook

Sheet PDRB
A1: DATA PDRB ATAS DASAR HARGA KONSTAN (ADHK) 2010 — Miliar Rupiah
B2: PDRB Subsektor (Seri 2010) | C2: PDRB ADHK Jawa Barat | I2: PDRB ADHK Kota Bogor
A3: Sumber: data unggahan pengguna (BPS). Seluruh angka dalam miliar rupiah, harga konstan 2010.
A4: Kode | B4: Lapangan Usaha | C4: 2019 | D4: 2020 | E4: 2021 | F4: 2022 | G4: 2023 | H4: 2024 | I4: 2019 | J4: 2020 | K4: 2021 | L4: 2022 | M4: 2023 | N4: 2024
A5: A | B5: Pertanian, Kehutanan, dan Perikanan | C5: 104596.75 | D5: 107000.79 | E5: 108406.55 | F5: 113186.39 | G5: 113308.54 | H5: 115104.77 | I5: 239.77 | J5: 245.16 | K5: 258.71 | L5: 267.41 | M5: 275.95 | N5: 279.23
A6: B | B6: Pertambangan dan Penggalian | C6: 24791.42 | D6: 23771.26 | E6: 23966.2 | F6: 23880.32 | G6: 23857.08 | H6: 23789.6 | I6: 0 | J6: 0 | K6: 0 | L6: 0 | M6: 0 | N6: 0
A7: C | B7: Industri Pengolahan | C7: 640760.96 | D7: 612799.43 | E7: 638689.32 | F7: 683420.25 | G7: 715811.26 | H7: 741041.45 | I7: 6065.72 | J7: 6015.39 | K7: 6283.63 | L7: 6603 | M7: 6864.58 | N7: 7032.53
A8: D | B8: Pengadaan Listrik dan Gas | C8: 5373.58 | D8: 4964.31 | E8: 5543.06 | F8: 5843.38 | G8: 5854.08 | H8: 5818.98 | I8: 771.59 | J8: 725.41 | K8: 813.13 | L8: 893.01 | M8: 869.6 | N8: 844.77
A9: E | B9: Pengadaan Air, Pengelolaan Sampah, Limbah dan Daur Ulang | C9: 1168.93 | D9: 1295.18 | E9: 1419.97 | F9: 1456.85 | G9: 1495.07 | H9: 1577.05 | I9: 32.73 | J9: 36.05 | K9: 39.77 | L9: 42.44 | M9: 47.06 | N9: 51.13
A10: F | B10: Konstruksi | C10: 126612.45 | D10: 119062.01 | E10: 126767.9 | F10: 126184.39 | G10: 133549.61 | H10: 143014.89 | I10: 3829.21 | J10: 3604.7 | K10: 3659.26 | L10: 3672.5 | M10: 4094.47 | N10: 4142.49
A11: G | B11: Perdagangan Besar dan Eceran | C11: 232878.84 | D11: 214374.85 | E11: 221203.99 | F11: 230532.56 | G11: 240583.83 | H11: 252244.61 | I11: 6744.72 | J11: 6210.45 | K11: 6379.3 | L11: 6722.52 | M11: 6973.02 | N11: 7191.2
A12: H | B12: Transportasi dan Pergudangan | C12: 71064.36 | D12: 68097.41 | E12: 67981.5 | F12: 75521.57 | G12: 83777.2 | H12: 94113.89 | I12: 3933.69 | J12: 3850.16 | K12: 3961.62 | L12: 4352.35 | M12: 4744.1 | N12: 5322.75
A13: I | B13: Penyediaan Akomodasi dan Makan Minum | C13: 40928.32 | D13: 38634.85 | E13: 38620.93 | F13: 42972.84 | G13: 46721.9 | H13: 49724.89 | I13: 1503.11 | J13: 1530.33 | K13: 1550.68 | L13: 1734.17 | M13: 1825.38 | N13: 1960.93
A14: J | B14: Informasi dan Komunikasi | C14: 63861.23 | D14: 85632.78 | E14: 91882.97 | F14: 97480.64 | G14: 105146 | H14: 113765.59 | I14: 2253.82 | J14: 3047.81 | K14: 3182.27 | L14: 3344.93 | M14: 3563.35 | N14: 3951.15
A15: K | B15: Jasa Keuangan dan Asuransi | C15: 36498.69 | D15: 36914.8 | E15: 39014.44 | F15: 38743.11 | G15: 40184.13 | H15: 41870.17 | I15: 2187.59 | J15: 2214.26 | K15: 2245.47 | L15: 2223.68 | M15: 2246.72 | N15: 2327.49
... A21: R,S,T, U | B21: Jasa lainnya | C21: 32912.01 | D21: 32045.37 | E21: 32305.31 | F21: 35559.49 | G21: 38253.41 | H21: 41286.15 | I21: 1131.8 | J21: 1097.74 | K21: 1195.11 | L21: 1336.93 | M21: 1388.12 | N21: 1514.21
B22: PRODUK DOMESTIK REGIONAL BRUTO | C22: =SUM(C5:C21) -> 1490959.7 | D22: =SUM(D5:D21) -> 1453380.7 | E22: =SUM(E5:E21) -> 1507746.4 | F22: =SUM(F5:F21) -> 1589984.9 | G22: =SUM(G5:G21) -> 1669421.5 | H22: =SUM(H5:H21) -> 1752071.2 | I22: =SUM(I5:I21) -> 32295.74 | J22: =SUM(J5:J21) -> 32162.74 | ... N22: =SUM(N5:N21) -> 38964.67

Sheet LQ
A1: ANALISIS LOCATION QUOTIENT (LQ) — KOTA BOGOR TERHADAP JAWA BARAT
A2: Rumus: LQ = (Xij / RVj) ÷ (Xi / RVi)
A3: Xij = PDRB sektor i Kota Bogor | RVj = total PDRB Kota Bogor | Xi = PDRB sektor i Jawa Barat | RVi = total PDRB Jawa Barat
A4: Kriteria: LQ > 1 = sektor basis (unggulan/ekspor) · LQ = 1 = swasembada · LQ < 1 = sektor non-basis
A6: Kode | B6: Lapangan Usaha | C6: LQ 2019 | D6: LQ 2020 | E6: LQ 2021 | F6: LQ 2022 | G6: LQ 2023 | H6: LQ 2024 | I6: Rata-rata LQ | J6: Kriteria | K6: Peringkat
A7: =PDRB!A5 -> A | B7: =PDRB!B5 -> Pertanian, Kehutanan, dan Perikanan | C7: =IFERROR((PDRB!I5/PDRB!$I$22)/(PDRB!C5/PDRB!$C$22),0) -> 0.1058272 | D7: =IFERROR((PDRB!J5/PDRB!$J$22)/(PDRB!D5/PDRB!$D$22),0) -> 0.10353543 | E7: =IFERROR((PDRB!K5/PDRB!$K$22)/(PDRB!E5/PDRB!$E$22),0) -> 0.10781968 | F7: =IFERROR((PDRB!L5/PDRB!$L$22)/(PDRB!F5/PDRB!$F$22),0) -> 0.10653889 | G7: =IFERROR((PDRB!M5/PDRB!$M$22)/(PDRB!G5/PDRB!$G$22),0) -> 0.10971925 | H7: =IFERROR((PDRB!N5/PDRB!$N$22)/(PDRB!H5/PDRB!$H$22),0) -> 0.1090811 | I7: =AVERAGE(C7:H7) -> 0.10708693 | J7: =IF(I7>=1,"Basis (unggulan)","Non-basis") -> Non-basis | K7: =RANK(I7,$I$7:$I$23) -> 16
A8: =PDRB!A6 -> B | B8: =PDRB!B6 -> Pertambangan dan Penggalian | C8: =IFERROR((PDRB!I6/PDRB!$I$22)/(PDRB!C6/PDRB!$C$22),0) -> 0 | D8: =IFERROR((PDRB!J6/PDRB!$J$22)/(PDRB!D6/PDRB!$D$22),0) -> 0 | E8: =IFERROR((PDRB!K6/PDRB!$K$22)/(PDRB!E6/PDRB!$E$22),0) -> 0 | F8: =IFERROR((PDRB!L6/PDRB!$L$22)/(PDRB!F6/PDRB!$F$22),0) -> 0 | G8: =IFERROR((PDRB!M6/PDRB!$M$22)/(PDRB!G6/PDRB!$G$22),0) -> 0 | H8: =IFERROR((PDRB!N6/PDRB!$N$22)/(PDRB!H6/PDRB!$H$22),0) -> 0 | I8: =AVERAGE(C8:H8) -> 0 | J8: =IF(I8>=1,"Basis (unggulan)","Non-basis") -> Non-basis | K8: =RANK(I8,$I$7:$I$23) -> 17
A9: =PDRB!A7 -> C | B9: =PDRB!B7 -> Industri Pengolahan | C9: =IFERROR((PDRB!I7/PDRB!$I$22)/(PDRB!C7/PDRB!$C$22),0) -> 0.4370257 | D9: =IFERROR((PDRB!J7/PDRB!$J$22)/(PDRB!D7/PDRB!$D$22),0) -> 0.44357983 | E9: =IFERROR((PDRB!K7/PDRB!$K$22)/(PDRB!E7/PDRB!$E$22),0) -> 0.44448928 | F9: =IFERROR((PDRB!L7/PDRB!$L$22)/(PDRB!F7/PDRB!$F$22),0) -> 0.43569061 | G9: =IFERROR((PDRB!M7/PDRB!$M$22)/(PDRB!G7/PDRB!$G$22),0) -> 0.43204654 | H9: =IFERROR((PDRB!N7/PDRB!$N$22)/(PDRB!H7/PDRB!$H$22),0) -> 0.42672672 | I9: =AVERAGE(C9:H9) -> 0.43659311 | J9: =IF(I9>=1,"Basis (unggulan)","Non-basis") -> Non-basis | K9: =RANK(I9,$I$7:$I$23) -> 15
A10: =PDRB!A8 -> D | B10: =PDRB!B8 -> Pengadaan Listrik dan Gas | C10: =IFERROR((PDRB!I8/PDRB!$I$22)/(PDRB!C8/PDRB!$C$22),0) -> 6.6289316 | D10: =IFERROR((PDRB!J8/PDRB!$J$22)/(PDRB!D8/PDRB!$D$22),0) -> 6.6031476 | E10: =IFERROR((PDRB!K8/PDRB!$K$22)/(PDRB!E8/PDRB!$E$22),0) -> 6.6275154 | F10: =IFERROR((PDRB!L8/PDRB!$L$22)/(PDRB!F8/PDRB!$F$22),0) -> 6.8915504 | G10: =IFERROR((PDRB!M8/PDRB!$M$22)/(PDRB!G8/PDRB!$G$22),0) -> 6.6923086 | H10: =IFERROR((PDRB!N8/PDRB!$N$22)/(PDRB!H8/PDRB!$H$22),0) -> 6.5278831 | I10: =AVERAGE(C10:H10) -> 6.6618894 | J10: =IF(I10>=1,"Basis (unggulan)","Non-basis") -> Basis (unggulan) | K10: =RANK(I10,$I$7:$I$23) -> 1
A11: =PDRB!A9 -> E | B11: =PDRB!B9 -> Pengadaan Air, Pengelolaan Sampah, Limbah dan Daur Ulang | C11: =IFERROR((PDRB!I9/PDRB!$I$22)/(PDRB!C9/PDRB!$C$22),0) -> 1.2926417 | D11: =IFERROR((PDRB!J9/PDRB!$J$22)/(PDRB!D9/PDRB!$D$22),0) -> 1.2577708 | E11: =IFERROR((PDRB!K9/PDRB!$K$22)/(PDRB!E9/PDRB!$E$22),0) -> 1.2653677 | F11: =IFERROR((PDRB!L9/PDRB!$L$22)/(PDRB!F9/PDRB!$F$22),0) -> 1.313667 | G11: =IFERROR((PDRB!M9/PDRB!$M$22)/(PDRB!G9/PDRB!$G$22),0) -> 1.4180955 | H11: =IFERROR((PDRB!N9/PDRB!$N$22)/(PDRB!H9/PDRB!$H$22),0) -> 1.4578441 | I11: =AVERAGE(C11:H11) -> 1.3342311 | J11: =IF(I11>=1,"Basis (unggulan)","Non-basis") -> Basis (unggulan) | K11: =RANK(I11,$I$7:$I$23) -> 11
A12: =PDRB!A10 -> F | B12: =PDRB!B10 -> Konstruksi | C12: =IFERROR((PDRB!I10/PDRB!$I$22)/(PDRB!C10/PDRB!$C$22),0) -> 1.3962187 | D12: =IFERROR((PDRB!J10/PDRB!$J$22)/(PDRB!D10/PDRB!$D$22),0) -> 1.368114 | E12: =IFERROR((PDRB!K10/PDRB!$K$22)/(PDRB!E10/PDRB!$E$22),0) -> 1.3041403 | F12: =IFERROR((PDRB!L10/PDRB!$L$22)/(PDRB!F10/PDRB!$F$22),0) -> 1.3124444 | G12: =IFERROR((PDRB!M10/PDRB!$M$22)/(PDRB!G10/PDRB!$G$22),0) -> 1.3812432 | H12: =IFERROR((PDRB!N10/PDRB!$N$22)/(PDRB!H10/PDRB!$H$22),0) -> 1.3024497 | I12: =AVERAGE(C12:H12) -> 1.3441017 | J12: =IF(I12>=1,"Basis (unggulan)","Non-basis") -> Basis (unggulan) | K12: =RANK(I12,$I$7:$I$23) -> 10
A13: =PDRB!A11 -> G | B13: =PDRB!B11 -> Perdagangan Besar dan Eceran | C13: =IFERROR((PDRB!I11/PDRB!$I$22)/(PDRB!C11/PDRB!$C$22),0) -> 1.3370713 | D13: =IFERROR((PDRB!J11/PDRB!$J$22)/(PDRB!D11/PDRB!$D$22),0) -> 1.3091084 | E13: =IFERROR((PDRB!K11/PDRB!$K$22)/(PDRB!E11/PDRB!$E$22),0) -> 1.302928 | F13: =IFERROR((PDRB!L11/PDRB!$L$22)/(PDRB!F11/PDRB!$F$22),0) -> 1.3149964 | G13: =IFERROR((PDRB!M11/PDRB!$M$22)/(PDRB!G11/PDRB!$G$22),0) -> 1.3057786 | H13: =IFERROR((PDRB!N11/PDRB!$N$22)/(PDRB!H11/PDRB!$H$22),0) -> 1.2819179 | I13: =AVERAGE(C13:H13) -> 1.3086334 | J13: =IF(I13>=1,"Basis (unggulan)","Non-basis") -> Basis (unggulan) | K13: =RANK(I13,$I$7:$I$23) -> 12
A14: =PDRB!A12 -> H | B14: =PDRB!B12 -> Transportasi dan Pergudangan | C14: =IFERROR((PDRB!I12/PDRB!$I$22)/(PDRB!C12/PDRB!$C$22),0) -> 2.5554592 | D14: =IFERROR((PDRB!J12/PDRB!$J$22)/(PDRB!D12/PDRB!$D$22),0) -> 2.5549037 | E14: =IFERROR((PDRB!K12/PDRB!$K$22)/(PDRB!E12/PDRB!$E$22),0) -> 2.6328275 | F14: =IFERROR((PDRB!L12/PDRB!$L$22)/(PDRB!F12/PDRB!$F$22),0) -> 2.598828 | G14: =IFERROR((PDRB!M12/PDRB!$M$22)/(PDRB!G12/PDRB!$G$22),0) -> 2.5511916 | H14: =IFERROR((PDRB!N12/PDRB!$N$22)/(PDRB!H12/PDRB!$H$22),0) -> 2.543098 | I14: =AVERAGE(C14:H14) -> 2.572718 | J14: =IF(I14>=1,"Basis (unggulan)","Non-basis") -> Basis (unggulan) | K14: =RANK(I14,$I$7:$I$23) -> 4
A15: =PDRB!A13 -> I | B15: =PDRB!B13 -> Penyediaan Akomodasi dan Makan Minum | C15: =IFERROR((PDRB!I13/PDRB!$I$22)/(PDRB!C13/PDRB!$C$22),0) -> 1.6954599 | D15: =IFERROR((PDRB!J13/PDRB!$J$22)/(PDRB!D13/PDRB!$D$22),0) -> 1.7899142 | E15: =IFERROR((PDRB!K13/PDRB!$K$22)/(PDRB!E13/PDRB!$E$22),0) -> 1.8140105 | F15: =IFERROR((PDRB!L13/PDRB!$L$22)/(PDRB!F13/PDRB!$F$22),0) -> 1.8197945 | G15: =IFERROR((PDRB!M13/PDRB!$M$22)/(PDRB!G13/PDRB!$G$22),0) -> 1.7601427 | H15: =IFERROR((PDRB!N13/PDRB!$N$22)/(PDRB!H13/PDRB!$H$22),0) -> 1.7732461 | I15: =AVERAGE(C15:H15) -> 1.775428 | J15: =IF(I15>=1,"Basis (unggulan)","Non-basis") -> Basis (unggulan) | K15: =RANK(I15,$I$7:$I$23) -> 6
A16: =PDRB!A14 -> J | B16: =PDRB!B14 -> Informasi dan Komunikasi | C16: =IFERROR((PDRB!I14/PDRB!$I$22)/(PDRB!C14/PDRB!$C$22),0) -> 1.6293058 | D16: =IFERROR((PDRB!J14/PDRB!$J$22)/(PDRB!D14/PDRB!$D$22),0) -> 1.6083264 | E16: =IFERROR((PDRB!K14/PDRB!$K$22)/(PDRB!E14/PDRB!$E$22),0) -> 1.5647406 | F16: =IFERROR((PDRB!L14/PDRB!$L$22)/(PDRB!F14/PDRB!$F$22),0) -> 1.5473673 | G16: =IFERROR((PDRB!M14/PDRB!$M$22)/(PDRB!G14/PDRB!$G$22),0) -> 1.5267953 | H16: =IFERROR((PDRB!N14/PDRB!$N$22)/(PDRB!H14/PDRB!$H$22),0) -> 1.5616847 | I16: =AVERAGE(C16:H16) -> 1.5730367 | J16: =IF(I16>=1,"Basis (unggulan)","Non-basis") -> Basis (unggulan) | K16: =RANK(I16,$I$7:$I$23) -> 9
A17: =PDRB!A15 -> K | B17: =PDRB!B15 -> Jasa Keuangan dan Asuransi | C17: =IFERROR((PDRB!I15/PDRB!$I$22)/(PDRB!C15/PDRB!$C$22),0) -> 2.767001 | D17: =IFERROR((PDRB!J15/PDRB!$J$22)/(PDRB!D15/PDRB!$D$22),0) -> 2.7105315 | E17: =IFERROR((PDRB!K15/PDRB!$K$22)/(PDRB!E15/PDRB!$E$22),0) -> 2.6002926 | F17: =IFERROR((PDRB!L15/PDRB!$L$22)/(PDRB!F15/PDRB!$F$22),0) -> 2.5882281 | G17: =IFERROR((PDRB!M15/PDRB!$M$22)/(PDRB!G15/PDRB!$G$22),0) -> 2.5188915 | H17: =IFERROR((PDRB!N15/PDRB!$N$22)/(PDRB!H15/PDRB!$H$22),0) -> 2.4995616 | I17: =AVERAGE(C17:H17) -> 2.6140844 | J17: =IF(I17>=1,"Basis (unggulan)","Non-basis") -> Basis (unggulan) | K17: =RANK(I17,$I$7:$I$23) -> 3
A18: =PDRB!A16 -> L | B18: =PDRB!B16 -> Real Estate | C18: =IFERROR((PDRB!I16/PDRB!$I$22)/(PDRB!C16/PDRB!$C$22),0) -> 1.7577942 | D18: =IFERROR((PDRB!J16/PDRB!$J$22)/(PDRB!D16/PDRB!$D$22),0) -> 1.6483058 | E18: =IFERROR((PDRB!K16/PDRB!$K$22)/(PDRB!E16/PDRB!$E$22),0) -> 1.6835584 | F18: =IFERROR((PDRB!L16/PDRB!$L$22)/(PDRB!F16/PDRB!$F$22),0) -> 1.7212328 | G18: =IFERROR((PDRB!M16/PDRB!$M$22)/(PDRB!G16/PDRB!$G$22),0) -> 1.6536177 | H18: =IFERROR((PDRB!N16/PDRB!$N$22)/(PDRB!H16/PDRB!$H$22),0) -> 1.6535629 | I18: =AVERAGE(C18:H18) -> 1.6863453 | J18: =IF(I18>=1,"Basis (unggulan)","Non-basis") -> Basis (unggulan) | K18: =RANK(I18,$I$7:$I$23) -> 7
... A23: =PDRB!A21 -> R,S,T, U | B23: =PDRB!B21 -> Jasa lainnya | C23: =IFERROR((PDRB!I21/PDRB!$I$22)/(PDRB!C21/PDRB!$C$22),0) -> 1.5875812 | D23: =IFERROR((PDRB!J21/PDRB!$J$22)/(PDRB!D21/PDRB!$D$22),0) -> 1.5479629 | E23: =IFERROR((PDRB!K21/PDRB!$K$22)/(PDRB!E21/PDRB!$E$22),0) -> 1.6713766 | F23: =IFERROR((PDRB!L21/PDRB!$L$22)/(PDRB!F21/PDRB!$F$22),0) -> 1.6954223 | G23: =IFERROR((PDRB!M21/PDRB!$M$22)/(PDRB!G21/PDRB!$G$22),0) -> 1.6348275 | H23: =IFERROR((PDRB!N21/PDRB!$N$22)/(PDRB!H21/PDRB!$H$22),0) -> 1.6491588 | I23: =AVERAGE(C23:H23) -> 1.6310549 | J23: =IF(I23>=1,"Basis (unggulan)","Non-basis") -> Basis (unggulan) | K23: =RANK(I23,$I$7:$I$23) -> 8
A25: Catatan: Sektor B (Pertambangan dan Penggalian) bernilai 0 di Kota Bogor sehingga LQ = 0 (sektor tidak ada).
A26: Jumlah sektor basis (LQ rata-rata ≥ 1): | I26: =COUNTIF($I$7:$I$23,">=1") -> 14

Sheet SSA
A1: ANALISIS SHIFT SHARE (SS) — KOTA BOGOR, WILAYAH REFERENSI: JAWA BARAT
A2: Rumus: Dij = Nij + Mij + Cij Nij = Yij × rn Mij = Yij × (rin − rn) Cij = Yij × (rij − rn)
A3: Yij = PDRB sektor i Kota Bogor tahun awal · rij = laju pertumbuhan sektor i Kota Bogor · rin = laju pertumbuhan sektor i Jawa Barat · rn = laju pertumbuhan total PDRB Jawa Barat
A5: Tahun awal (t₀) | D5: 2019 | F5: ← sel kuning = input, boleh diubah (2019–2024); seluruh tabel ikut menghitung ulang
A6: Tahun akhir (t) | D6: 2024
A7: Total PDRB Jawa Barat t₀ (Yn t₀) | D7: =INDEX(PDRB!$C$22:$H$22,MATCH($D$5,PDRB!$C$4:$H$4,0)) -> 1490959.7
A8: Total PDRB Jawa Barat t (Yn t) | D8: =INDEX(PDRB!$C$22:$H$22,MATCH($D$6,PDRB!$C$4:$H$4,0)) -> 1752071.2
A9: rn = (Yn t − Yn t₀) / Yn t₀ | D9: =(D8-D7)/D7 -> 0.17512982
A11: Kode | B11: Lapangan Usaha | C11: Yij t₀ (Bogor) | D11: Yij t (Bogor) | E11: Yin t₀ (Jabar) | F11: Yin t (Jabar) | G11: rij (Bogor) | H11: rin (Jabar) | I11: rn (Jabar total) | J11: Nij = Yij × rn | K11: Mij = Yij × (rin−rn) | L11: Cij (panduan) = Yij × (rij−rn) | M11: Dij (panduan) = Nij+Mij+Cij | N11: Cij (identitas) = Yij × (rij−rin) | O11: Dij (identitas) = Nij+Mij+Cij | P11: ΔPDRB aktual = Yij t − Yij t₀ | Q11: Selisih (Dij identitas − ΔPDRB)
A12: =PDRB!A5 -> A | B12: =PDRB!B5 -> Pertanian, Kehutanan, dan Perikanan | C12: =INDEX(PDRB!$I5:$N5,MATCH($D$5,PDRB!$I$4:$N$4,0)) -> 239.77 | D12: =INDEX(PDRB!$I5:$N5,MATCH($D$6,PDRB!$I$4:$N$4,0)) -> 279.23 | E12: =INDEX(PDRB!$C5:$H5,MATCH($D$5,PDRB!$C$4:$H$4,0)) -> 104596.75 | F12: =INDEX(PDRB!$C5:$H5,MATCH($D$6,PDRB!$C$4:$H$4,0)) -> 115104.77 | G12: =IFERROR((D12-C12)/C12,0) -> 0.16457438 | H12: =IFERROR((F12-E12)/E12,0) -> 0.1004622 | I12: =$D$9 -> 0.17512982 | J12: =C12*I12 -> 41.990876 | K12: =C12*(H12-I12) -> -17.903054 | L12: =C12*(G12-I12) -> -2.5308763 | M12: =J12+K12+L12 -> 21.556946 | N12: =C12*(G12-H12) -> 15.372177 | O12: =J12+K12+N12 -> 39.46 | P12: =D12-C12 -> 39.46 | Q12: =O12-P12 -> 0
A13: =PDRB!A6 -> B | B13: =PDRB!B6 -> Pertambangan dan Penggalian | C13: =INDEX(PDRB!$I6:$N6,MATCH($D$5,PDRB!$I$4:$N$4,0)) -> 0 | D13: =INDEX(PDRB!$I6:$N6,MATCH($D$6,PDRB!$I$4:$N$4,0)) -> 0 | E13: =INDEX(PDRB!$C6:$H6,MATCH($D$5,PDRB!$C$4:$H$4,0)) -> 24791.42 | F13: =INDEX(PDRB!$C6:$H6,MATCH($D$6,PDRB!$C$4:$H$4,0)) -> 23789.6 | G13: =IFERROR((D13-C13)/C13,0) -> 0 | H13: =IFERROR((F13-E13)/E13,0) -> -0.040409948 | I13: =$D$9 -> 0.17512982 | J13: =C13*I13 -> 0 | K13: =C13*(H13-I13) -> 0 | L13: =C13*(G13-I13) -> 0 | M13: =J13+K13+L13 -> 0 | N13: =C13*(G13-H13) -> 0 | O13: =J13+K13+N13 -> 0 | P13: =D13-C13 -> 0 | Q13: =O13-P13 -> 0
A14: =PDRB!A7 -> C | B14: =PDRB!B7 -> Industri Pengolahan | C14: =INDEX(PDRB!$I7:$N7,MATCH($D$5,PDRB!$I$4:$N$4,0)) -> 6065.72 | D14: =INDEX(PDRB!$I7:$N7,MATCH($D$6,PDRB!$I$4:$N$4,0)) -> 7032.53 | E14: =INDEX(PDRB!$C7:$H7,MATCH($D$5,PDRB!$C$4:$H$4,0)) -> 640760.96 | F14: =INDEX(PDRB!$C7:$H7,MATCH($D$6,PDRB!$C$4:$H$4,0)) -> 741041.45 | G14: =IFERROR((D14-C14)/C14,0) -> 0.15938916 | H14: =IFERROR((F14-E14)/E14,0) -> 0.15650218 | I14: =$D$9 -> 0.17512982 | J14: =C14*I14 -> 1062.2884 | K14: =C14*(H14-I14) -> -112.99001 | L14: =C14*(G14-I14) -> -95.478436 | M14: =J14+K14+L14 -> 853.81999 | N14: =C14*(G14-H14) -> 17.511569 | O14: =J14+K14+N14 -> 966.81 | P14: =D14-C14 -> 966.81 | Q14: =O14-P14 -> 0
A15: =PDRB!A8 -> D | B15: =PDRB!B8 -> Pengadaan Listrik dan Gas | C15: =INDEX(PDRB!$I8:$N8,MATCH($D$5,PDRB!$I$4:$N$4,0)) -> 771.59 | D15: =INDEX(PDRB!$I8:$N8,MATCH($D$6,PDRB!$I$4:$N$4,0)) -> 844.77 | E15: =INDEX(PDRB!$C8:$H8,MATCH($D$5,PDRB!$C$4:$H$4,0)) -> 5373.58 | F15: =INDEX(PDRB!$C8:$H8,MATCH($D$6,PDRB!$C$4:$H$4,0)) -> 5818.98 | G15: =IFERROR((D15-C15)/C15,0) -> 0.094843116 | H15: =IFERROR((F15-E15)/E15,0) -> 0.082887014 | I15: =$D$9 -> 0.17512982 | J15: =C15*I15 -> 135.12842 | K15: =C15*(H15-I15) -> -71.173625 | L15: =C15*(G15-I15) -> -61.948416 | M15: =J15+K15+L15 -> 2.0063752 | N15: =C15*(G15-H15) -> 9.225209 | O15: =J15+K15+N15 -> 73.18 | P15: =D15-C15 -> 73.18 | Q15: =O15-P15 -> 0
A16: =PDRB!A9 -> E | B16: =PDRB!B9 -> Pengadaan Air, Pengelolaan Sampah, Limbah dan Daur Ulang | C16: =INDEX(PDRB!$I9:$N9,MATCH($D$5,PDRB!$I$4:$N$4,0)) -> 32.73 | D16: =INDEX(PDRB!$I9:$N9,MATCH($D$6,PDRB!$I$4:$N$4,0)) -> 51.13 | E16: =INDEX(PDRB!$C9:$H9,MATCH($D$5,PDRB!$C$4:$H$4,0)) -> 1168.93 | F16: =INDEX(PDRB!$C9:$H9,MATCH($D$6,PDRB!$C$4:$H$4,0)) -> 1577.05 | G16: =IFERROR((D16-C16)/C16,0) -> 0.56217537 | H16: =IFERROR((F16-E16)/E16,0) -> 0.34913981 | I16: =$D$9 -> 0.17512982 | J16: =C16*I16 -> 5.7319989 | K16: =C16*(H16-I16) -> 5.6953471 | L16: =C16*(G16-I16) -> 12.668001 | M16: =J16+K16+L16 -> 24.095347 | N16: =C16*(G16-H16) -> 6.972654 | O16: =J16+K16+N16 -> 18.4 | P16: =D16-C16 -> 18.4 | Q16: =O16-P16 -> 0
A17: =PDRB!A10 -> F | B17: =PDRB!B10 -> Konstruksi | C17: =INDEX(PDRB!$I10:$N10,MATCH($D$5,PDRB!$I$4:$N$4,0)) -> 3829.21 | D17: =INDEX(PDRB!$I10:$N10,MATCH($D$6,PDRB!$I$4:$N$4,0)) -> 4142.49 | E17: =INDEX(PDRB!$C10:$H10,MATCH($D$5,PDRB!$C$4:$H$4,0)) -> 126612.45 | F17: =INDEX(PDRB!$C10:$H10,MATCH($D$6,PDRB!$C$4:$H$4,0)) -> 143014.89 | G17: =IFERROR((D17-C17)/C17,0) -> 0.08181322 | H17: =IFERROR((F17-E17)/E17,0) -> 0.1295484 | I17: =$D$9 -> 0.17512982 | J17: =C17*I17 -> 670.60885 | K17: =C17*(H17-I17) -> -174.54083 | L17: =C17*(G17-I17) -> -357.32885 | M17: =J17+K17+L17 -> 138.73917 | N17: =C17*(G17-H17) -> -182.78802 | O17: =J17+K17+N17 -> 313.28 | P17: =D17-C17 -> 313.28 | Q17: =O17-P17 -> 0
A18: =PDRB!A11 -> G | B18: =PDRB!B11 -> Perdagangan Besar dan Eceran | C18: =INDEX(PDRB!$I11:$N11,MATCH($D$5,PDRB!$I$4:$N$4,0)) -> 6744.72 | D18: =INDEX(PDRB!$I11:$N11,MATCH($D$6,PDRB!$I$4:$N$4,0)) -> 7191.2 | E18: =INDEX(PDRB!$C11:$H11,MATCH($D$5,PDRB!$C$4:$H$4,0)) -> 232878.84 | F18: =INDEX(PDRB!$C11:$H11,MATCH($D$6,PDRB!$C$4:$H$4,0)) -> 252244.61 | G18: =IFERROR((D18-C18)/C18,0) -> 0.066196966 | H18: =IFERROR((F18-E18)/E18,0) -> 0.083158135 | I18: =$D$9 -> 0.17512982 | J18: =C18*I18 -> 1181.2016 | K18: =C18*(H18-I18) -> -620.32325 | L18: =C18*(G18-I18) -> -734.72158 | M18: =J18+K18+L18 -> -173.84325 | N18: =C18*(G18-H18) -> -114.39834 | O18: =J18+K18+N18 -> 446.48 | P18: =D18-C18 -> 446.48 | Q18: =O18-P18 -> 0
A19: =PDRB!A12 -> H | B19: =PDRB!B12 -> Transportasi dan Pergudangan | C19: =INDEX(PDRB!$I12:$N12,MATCH($D$5,PDRB!$I$4:$N$4,0)) -> 3933.69 | D19: =INDEX(PDRB!$I12:$N12,MATCH($D$6,PDRB!$I$4:$N$4,0)) -> 5322.75 | E19: =INDEX(PDRB!$C12:$H12,MATCH($D$5,PDRB!$C$4:$H$4,0)) -> 71064.36 | F19: =INDEX(PDRB!$C12:$H12,MATCH($D$6,PDRB!$C$4:$H$4,0)) -> 94113.89 | G19: =IFERROR((D19-C19)/C19,0) -> 0.35311883 | H19: =IFERROR((F19-E19)/E19,0) -> 0.32434725 | I19: =$D$9 -> 0.17512982 | J19: =C19*I19 -> 688.90641 | K19: =C19*(H19-I19) -> 586.97514 | L19: =C19*(G19-I19) -> 700.15359 | M19: =J19+K19+L19 -> 1976.0351 | N19: =C19*(G19-H19) -> 113.17845 | O19: =J19+K19+N19 -> 1389.06 | P19: =D19-C19 -> 1389.06 | Q19: =O19-P19 -> 0
A20: =PDRB!A13 -> I | B20: =PDRB!B13 -> Penyediaan Akomodasi dan Makan Minum | C20: =INDEX(PDRB!$I13:$N13,MATCH($D$5,PDRB!$I$4:$N$4,0)) -> 1503.11 | D20: =INDEX(PDRB!$I13:$N13,MATCH($D$6,PDRB!$I$4:$N$4,0)) -> 1960.93 | E20: =INDEX(PDRB!$C13:$H13,MATCH($D$5,PDRB!$C$4:$H$4,0)) -> 40928.32 | F20: =INDEX(PDRB!$C13:$H13,MATCH($D$6,PDRB!$C$4:$H$4,0)) -> 49724.89 | G20: =IFERROR((D20-C20)/C20,0) -> 0.30458183 | H20: =IFERROR((F20-E20)/E20,0) -> 0.21492624 | I20: =$D$9 -> 0.17512982 | J20: =C20*I20 -> 263.23938 | K20: =C20*(H20-I20) -> 59.818403 | L20: =C20*(G20-I20) -> 194.58062 | M20: =J20+K20+L20 -> 517.6384 | N20: =C20*(G20-H20) -> 134.76222 | O20: =J20+K20+N20 -> 457.82 | P20: =D20-C20 -> 457.82 | Q20: =O20-P20 -> 0
A21: =PDRB!A14 -> J | B21: =PDRB!B14 -> Informasi dan Komunikasi | C21: =INDEX(PDRB!$I14:$N14,MATCH($D$5,PDRB!$I$4:$N$4,0)) -> 2253.82 | D21: =INDEX(PDRB!$I14:$N14,MATCH($D$6,PDRB!$I$4:$N$4,0)) -> 3951.15 | E21: =INDEX(PDRB!$C14:$H14,MATCH($D$5,PDRB!$C$4:$H$4,0)) -> 63861.23 | F21: =INDEX(PDRB!$C14:$H14,MATCH($D$6,PDRB!$C$4:$H$4,0)) -> 113765.59 | G21: =IFERROR((D21-C21)/C21,0) -> 0.75309031 | H21: =IFERROR((F21-E21)/E21,0) -> 0.78145003 | I21: =$D$9 -> 0.17512982 | J21: =C21*I21 -> 394.71109 | K21: =C21*(H21-I21) -> 1366.5366 | L21: =C21*(G21-I21) -> 1302.6189 | M21: =J21+K21+L21 -> 3063.8666 | N21: =C21*(G21-H21) -> -63.917703 | O21: =J21+K21+N21 -> 1697.33 | P21: =D21-C21 -> 1697.33 | Q21: =O21-P21 -> 0
A22: =PDRB!A15 -> K | B22: =PDRB!B15 -> Jasa Keuangan dan Asuransi | C22: =INDEX(PDRB!$I15:$N15,MATCH($D$5,PDRB!$I$4:$N$4,0)) -> 2187.59 | D22: =INDEX(PDRB!$I15:$N15,MATCH($D$6,PDRB!$I$4:$N$4,0)) -> 2327.49 | E22: =INDEX(PDRB!$C15:$H15,MATCH($D$5,PDRB!$C$4:$H$4,0)) -> 36498.69 | F22: =INDEX(PDRB!$C15:$H15,MATCH($D$6,PDRB!$C$4:$H$4,0)) -> 41870.17 | G22: =IFERROR((D22-C22)/C22,0) -> 0.063951655 | H22: =IFERROR((F22-E22)/E22,0) -> 0.14716912 | I22: =$D$9 -> 0.17512982 | J22: =C22*I22 -> 383.11224 | K22: =C22*(H22-I22) -> -61.166547 | L22: =C22*(G22-I22) -> -243.21224 | M22: =J22+K22+L22 -> 78.733453 | N22: =C22*(G22-H22) -> -182.04569 | O22: =J22+K22+N22 -> 139.9 | P22: =D22-C22 -> 139.9 | Q22: =O22-P22 -> 0
A23: =PDRB!A16 -> L | B23: =PDRB!B16 -> Real Estate | C23: =INDEX(PDRB!$I16:$N16,MATCH($D$5,PDRB!$I$4:$N$4,0)) -> 736.54 | D23: =INDEX(PDRB!$I16:$N16,MATCH($D$6,PDRB!$I$4:$N$4,0)) -> 957.85 | E23: =INDEX(PDRB!$C16:$H16,MATCH($D$5,PDRB!$C$4:$H$4,0)) -> 19344.12 | F23: =INDEX(PDRB!$C16:$H16,MATCH($D$6,PDRB!$C$4:$H$4,0)) -> 26046.99 | G23: =IFERROR((D23-C23)/C23,0) -> 0.30047248 | H23: =IFERROR((F23-E23)/E23,0) -> 0.34650685 | I23: =$D$9 -> 0.17512982 | J23: =C23*I23 -> 128.99012 | K23: =C23*(H23-I23) -> 126.22604 | L23: =C23*(G23-I23) -> 92.319884 | M23: =J23+K23+L23 -> 347.53604 | N23: =C23*(G23-H23) -> -33.906152 | O23: =J23+K23+N23 -> 221.31 | P23: =D23-C23 -> 221.31 | Q23: =O23-P23 -> 0
... A28: =PDRB!A21 -> R,S,T, U | B28: =PDRB!B21 -> Jasa lainnya | C28: =INDEX(PDRB!$I21:$N21,MATCH($D$5,PDRB!$I$4:$N$4,0)) -> 1131.8 | D28: =INDEX(PDRB!$I21:$N21,MATCH($D$6,PDRB!$I$4:$N$4,0)) -> 1514.21 | E28: =INDEX(PDRB!$C21:$H21,MATCH($D$5,PDRB!$C$4:$H$4,0)) -> 32912.01 | F28: =INDEX(PDRB!$C21:$H21,MATCH($D$6,PDRB!$C$4:$H$4,0)) -> 41286.15 | G28: =IFERROR((D28-C28)/C28,0) -> 0.33787772 | H28: =IFERROR((F28-E28)/E28,0) -> 0.25444025 | I28: =$D$9 -> 0.17512982 | J28: =C28*I28 -> 198.21193 | K28: =C28*(H28-I28) -> 89.763546 | L28: =C28*(G28-I28) -> 184.19807 | M28: =J28+K28+L28 -> 472.17355 | N28: =C28*(G28-H28) -> 94.434527 | O28: =J28+K28+N28 -> 382.41 | P28: =D28-C28 -> 382.41 | Q28: =O28-P28 -> 0
B29: JUMLAH | C29: =SUM(C12:C28) -> 32295.74 | D29: =SUM(D12:D28) -> 38964.67 | J29: =SUM(J12:J28) -> 5655.947 | K29: =SUM(K12:K28) -> 1054.8173 | L29: =SUM(L12:L28) -> 1012.983 | M29: =SUM(M12:M28) -> 7723.7473 | N29: =SUM(N12:N28) -> -41.83437 | O29: =SUM(O12:O28) -> 6668.93 | P29: =SUM(P12:P28) -> 6668.93 | Q29: =SUM(Q12:Q28) -> -1.4210855e-14
A31: CATATAN PENTING MENGENAI RUMUS Cij
A32: 1. Kolom L memakai rumus persis seperti dokumen yang diunggah: Cij = Yij × (rij − rn).
A33: 2. Dengan rumus tersebut, identitas Dij = Nij + Mij + Cij TIDAK sama dengan perubahan PDRB aktual, karena komponen (rin − rn) terhitung dua kali.
A34: Secara aljabar: Yij(rij − rn) = Yij(rin − rn) + Yij(rij − rin) = Mij + Cij_identitas, sehingga Cij versi panduan sebenarnya = pergeseran bersih (net shift) Mij + Cij.
A35: 3. Kolom N adalah versi yang menutup identitas: Cij = Yij × (rij − rin). Dengan versi ini Dij = Nij + Mij + Cij = ΔPDRB aktual, dibuktikan kolom Q yang seluruhnya bernilai 0.
A36: 4. Keduanya disajikan agar dapat dicek. Untuk klasifikasi Tipologi, dipakai kolom L (versi panduan) sebagai "nilai SSA"; kolom N disajikan sebagai pembanding di sheet Klassen.
A37: 5. Wilayah referensi memakai Jawa Barat (bukan nasional) karena data yang tersedia hanya PDRB Jawa Barat dan Kota Bogor. Notasi "n" pada rumus dibaca sebagai Jawa Barat.

Sheet Klassen
A1: TIPOLOGI SEKTOR (MATRIKS LQ × SHIFT SHARE) — KOTA BOGOR 2019–2024
A2: Kuadran I: LQ ≥ 1 & SSA (+) · Kuadran II: LQ < 1 & SSA (+) · Kuadran III: LQ ≥ 1 & SSA (−) · Kuadran IV: LQ < 1 & SSA (−)
A3: Nilai SSA yang dipakai = Cij versi panduan (kolom L sheet SSA) = Yij × (rij − rn), yaitu pergeseran bersih sektor terhadap pertumbuhan Jawa Barat.
A5: Kode | B5: Lapangan Usaha | C5: LQ rata-rata | D5: Kriteria LQ | E5: Nilai SSA (Cij) | F5: Kriteria SSA | G5: Kuadran | H5: Klasifikasi Sektor | I5: Kuadran (versi Cij identitas) | J5: Cij identitas
A6: =PDRB!A5 -> A | B6: =PDRB!B5 -> Pertanian, Kehutanan, dan Perikanan | C6: =LQ!I7 -> 0.10708693 | D6: =IF(C6>=1,"LQ ≥ 1 (basis)","LQ < 1 (non-basis)") -> LQ < 1 (non-basis) | E6: =SSA!L12 -> -2.5308763 | F6: =IF(E6>0,"SSA (+)","SSA (−)") -> SSA (−) | G6: =IF(AND(C6>=1,E6>0),"Kuadran I",IF(AND(C6<1,E6>0),"Kuadran II",IF(AND(C6>=1,E6<=0),"Kuadran III","Kuadran IV"))) -> Kuadran IV | H6: =IF(G6="Kuadran I","Maju dan tumbuh cepat",IF(G6="Kuadran II","Potensial / berkembang cepat",IF(G6="Kuadran III","Maju tapi tertekan","Relatif tertinggal"))) -> Relatif tertinggal | I6: =IF(AND(C6>=1,J6>0),"Kuadran I",IF(AND(C6<1,J6>0),"Kuadran II",IF(AND(C6>=1,J6<=0),"Kuadran III","Kuadran IV"))) -> Kuadran II | J6: =SSA!N12 -> 15.372177
A7: =PDRB!A6 -> B | B7: =PDRB!B6 -> Pertambangan dan Penggalian | C7: =LQ!I8 -> 0 | D7: =IF(C7>=1,"LQ ≥ 1 (basis)","LQ < 1 (non-basis)") -> LQ < 1 (non-basis) | E7: =SSA!L13 -> 0 | F7: =IF(E7>0,"SSA (+)","SSA (−)") -> SSA (−) | G7: =IF(AND(C7>=1,E7>0),"Kuadran I",IF(AND(C7<1,E7>0),"Kuadran II",IF(AND(C7>=1,E7<=0),"Kuadran III","Kuadran IV"))) -> Kuadran IV | H7: =IF(G7="Kuadran I","Maju dan tumbuh cepat",IF(G7="Kuadran II","Potensial / berkembang cepat",IF(G7="Kuadran III","Maju tapi tertekan","Relatif tertinggal"))) -> Relatif tertinggal | I7: =IF(AND(C7>=1,J7>0),"Kuadran I",IF(AND(C7<1,J7>0),"Kuadran II",IF(AND(C7>=1,J7<=0),"Kuadran III","Kuadran IV"))) -> Kuadran IV | J7: =SSA!N13 -> 0
A8: =PDRB!A7 -> C | B8: =PDRB!B7 -> Industri Pengolahan | C8: =LQ!I9 -> 0.43659311 | D8: =IF(C8>=1,"LQ ≥ 1 (basis)","LQ < 1 (non-basis)") -> LQ < 1 (non-basis) | E8: =SSA!L14 -> -95.478436 | F8: =IF(E8>0,"SSA (+)","SSA (−)") -> SSA (−) | G8: =IF(AND(C8>=1,E8>0),"Kuadran I",IF(AND(C8<1,E8>0),"Kuadran II",IF(AND(C8>=1,E8<=0),"Kuadran III","Kuadran IV"))) -> Kuadran IV | H8: =IF(G8="Kuadran I","Maju dan tumbuh cepat",IF(G8="Kuadran II","Potensial / berkembang cepat",IF(G8="Kuadran III","Maju tapi tertekan","Relatif tertinggal"))) -> Relatif tertinggal | I8: =IF(AND(C8>=1,J8>0),"Kuadran I",IF(AND(C8<1,J8>0),"Kuadran II",IF(AND(C8>=1,J8<=0),"Kuadran III","Kuadran IV"))) -> Kuadran II | J8: =SSA!N14 -> 17.511569
A9: =PDRB!A8 -> D | B9: =PDRB!B8 -> Pengadaan Listrik dan Gas | C9: =LQ!I10 -> 6.6618894 | D9: =IF(C9>=1,"LQ ≥ 1 (basis)","LQ < 1 (non-basis)") -> LQ ≥ 1 (basis) | E9: =SSA!L15 -> -61.948416 | F9: =IF(E9>0,"SSA (+)","SSA (−)") -> SSA (−) | G9: =IF(AND(C9>=1,E9>0),"Kuadran I",IF(AND(C9<1,E9>0),"Kuadran II",IF(AND(C9>=1,E9<=0),"Kuadran III","Kuadran IV"))) -> Kuadran III | H9: =IF(G9="Kuadran I","Maju dan tumbuh cepat",IF(G9="Kuadran II","Potensial / berkembang cepat",IF(G9="Kuadran III","Maju tapi tertekan","Relatif tertinggal"))) -> Maju tapi tertekan | I9: =IF(AND(C9>=1,J9>0),"Kuadran I",IF(AND(C9<1,J9>0),"Kuadran II",IF(AND(C9>=1,J9<=0),"Kuadran III","Kuadran IV"))) -> Kuadran I | J9: =SSA!N15 -> 9.225209
A10: =PDRB!A9 -> E | B10: =PDRB!B9 -> Pengadaan Air, Pengelolaan Sampah, Limbah dan Daur Ulang | C10: =LQ!I11 -> 1.3342311 | D10: =IF(C10>=1,"LQ ≥ 1 (basis)","LQ < 1 (non-basis)") -> LQ ≥ 1 (basis) | E10: =SSA!L16 -> 12.668001 | F10: =IF(E10>0,"SSA (+)","SSA (−)") -> SSA (+) | G10: =IF(AND(C10>=1,E10>0),"Kuadran I",IF(AND(C10<1,E10>0),"Kuadran II",IF(AND(C10>=1,E10<=0),"Kuadran III","Kuadran IV"))) -> Kuadran I | H10: =IF(G10="Kuadran I","Maju dan tumbuh cepat",IF(G10="Kuadran II","Potensial / berkembang cepat",IF(G10="Kuadran III","Maju tapi tertekan","Relatif tertinggal"))) -> Maju dan tumbuh cepat | I10: =IF(AND(C10>=1,J10>0),"Kuadran I",IF(AND(C10<1,J10>0),"Kuadran II",IF(AND(C10>=1,J10<=0),"Kuadran III","Kuadran IV"))) -> Kuadran I | J10: =SSA!N16 -> 6.972654
A11: =PDRB!A10 -> F | B11: =PDRB!B10 -> Konstruksi | C11: =LQ!I12 -> 1.3441017 | D11: =IF(C11>=1,"LQ ≥ 1 (basis)","LQ < 1 (non-basis)") -> LQ ≥ 1 (basis) | E11: =SSA!L17 -> -357.32885 | F11: =IF(E11>0,"SSA (+)","SSA (−)") -> SSA (−) | G11: =IF(AND(C11>=1,E11>0),"Kuadran I",IF(AND(C11<1,E11>0),"Kuadran II",IF(AND(C11>=1,E11<=0),"Kuadran III","Kuadran IV"))) -> Kuadran III | H11: =IF(G11="Kuadran I","Maju dan tumbuh cepat",IF(G11="Kuadran II","Potensial / berkembang cepat",IF(G11="Kuadran III","Maju tapi tertekan","Relatif tertinggal"))) -> Maju tapi tertekan | I11: =IF(AND(C11>=1,J11>0),"Kuadran I",IF(AND(C11<1,J11>0),"Kuadran II",IF(AND(C11>=1,J11<=0),"Kuadran III","Kuadran IV"))) -> Kuadran III | J11: =SSA!N17 -> -182.78802
A12: =PDRB!A11 -> G | B12: =PDRB!B11 -> Perdagangan Besar dan Eceran | C12: =LQ!I13 -> 1.3086334 | D12: =IF(C12>=1,"LQ ≥ 1 (basis)","LQ < 1 (non-basis)") -> LQ ≥ 1 (basis) | E12: =SSA!L18 -> -734.72158 | F12: =IF(E12>0,"SSA (+)","SSA (−)") -> SSA (−) | G12: =IF(AND(C12>=1,E12>0),"Kuadran I",IF(AND(C12<1,E12>0),"Kuadran II",IF(AND(C12>=1,E12<=0),"Kuadran III","Kuadran IV"))) -> Kuadran III | H12: =IF(G12="Kuadran I","Maju dan tumbuh cepat",IF(G12="Kuadran II","Potensial / berkembang cepat",IF(G12="Kuadran III","Maju tapi tertekan","Relatif tertinggal"))) -> Maju tapi tertekan | I12: =IF(AND(C12>=1,J12>0),"Kuadran I",IF(AND(C12<1,J12>0),"Kuadran II",IF(AND(C12>=1,J12<=0),"Kuadran III","Kuadran IV"))) -> Kuadran III | J12: =SSA!N18 -> -114.39834
A13: =PDRB!A12 -> H | B13: =PDRB!B12 -> Transportasi dan Pergudangan | C13: =LQ!I14 -> 2.572718 | D13: =IF(C13>=1,"LQ ≥ 1 (basis)","LQ < 1 (non-basis)") -> LQ ≥ 1 (basis) | E13: =SSA!L19 -> 700.15359 | F13: =IF(E13>0,"SSA (+)","SSA (−)") -> SSA (+) | G13: =IF(AND(C13>=1,E13>0),"Kuadran I",IF(AND(C13<1,E13>0),"Kuadran II",IF(AND(C13>=1,E13<=0),"Kuadran III","Kuadran IV"))) -> Kuadran I | H13: =IF(G13="Kuadran I","Maju dan tumbuh cepat",IF(G13="Kuadran II","Potensial / berkembang cepat",IF(G13="Kuadran III","Maju tapi tertekan","Relatif tertinggal"))) -> Maju dan tumbuh cepat | I13: =IF(AND(C13>=1,J13>0),"Kuadran I",IF(AND(C13<1,J13>0),"Kuadran II",IF(AND(C13>=1,J13<=0),"Kuadran III","Kuadran IV"))) -> Kuadran I | J13: =SSA!N19 -> 113.17845
A14: =PDRB!A13 -> I | B14: =PDRB!B13 -> Penyediaan Akomodasi dan Makan Minum | C14: =LQ!I15 -> 1.775428 | D14: =IF(C14>=1,"LQ ≥ 1 (basis)","LQ < 1 (non-basis)") -> LQ ≥ 1 (basis) | E14: =SSA!L20 -> 194.58062 | F14: =IF(E14>0,"SSA (+)","SSA (−)") -> SSA (+) | G14: =IF(AND(C14>=1,E14>0),"Kuadran I",IF(AND(C14<1,E14>0),"Kuadran II",IF(AND(C14>=1,E14<=0),"Kuadran III","Kuadran IV"))) -> Kuadran I | H14: =IF(G14="Kuadran I","Maju dan tumbuh cepat",IF(G14="Kuadran II","Potensial / berkembang cepat",IF(G14="Kuadran III","Maju tapi tertekan","Relatif tertinggal"))) -> Maju dan tumbuh cepat | I14: =IF(AND(C14>=1,J14>0),"Kuadran I",IF(AND(C14<1,J14>0),"Kuadran II",IF(AND(C14>=1,J14<=0),"Kuadran III","Kuadran IV"))) -> Kuadran I | J14: =SSA!N20 -> 134.76222
A15: =PDRB!A14 -> J | B15: =PDRB!B14 -> Informasi dan Komunikasi | C15: =LQ!I16 -> 1.5730367 | D15: =IF(C15>=1,"LQ ≥ 1 (basis)","LQ < 1 (non-basis)") -> LQ ≥ 1 (basis) | E15: =SSA!L21 -> 1302.6189 | F15: =IF(E15>0,"SSA (+)","SSA (−)") -> SSA (+) | G15: =IF(AND(C15>=1,E15>0),"Kuadran I",IF(AND(C15<1,E15>0),"Kuadran II",IF(AND(C15>=1,E15<=0),"Kuadran III","Kuadran IV"))) -> Kuadran I | H15: =IF(G15="Kuadran I","Maju dan tumbuh cepat",IF(G15="Kuadran II","Potensial / berkembang cepat",IF(G15="Kuadran III","Maju tapi tertekan","Relatif tertinggal"))) -> Maju dan tumbuh cepat | I15: =IF(AND(C15>=1,J15>0),"Kuadran I",IF(AND(C15<1,J15>0),"Kuadran II",IF(AND(C15>=1,J15<=0),"Kuadran III","Kuadran IV"))) -> Kuadran III | J15: =SSA!N21 -> -63.917703
A16: =PDRB!A15 -> K | B16: =PDRB!B15 -> Jasa Keuangan dan Asuransi | C16: =LQ!I17 -> 2.6140844 | D16: =IF(C16>=1,"LQ ≥ 1 (basis)","LQ < 1 (non-basis)") -> LQ ≥ 1 (basis) | E16: =SSA!L22 -> -243.21224 | F16: =IF(E16>0,"SSA (+)","SSA (−)") -> SSA (−) | G16: =IF(AND(C16>=1,E16>0),"Kuadran I",IF(AND(C16<1,E16>0),"Kuadran II",IF(AND(C16>=1,E16<=0),"Kuadran III","Kuadran IV"))) -> Kuadran III | H16: =IF(G16="Kuadran I","Maju dan tumbuh cepat",IF(G16="Kuadran II","Potensial / berkembang cepat",IF(G16="Kuadran III","Maju tapi tertekan","Relatif tertinggal"))) -> Maju tapi tertekan | I16: =IF(AND(C16>=1,J16>0),"Kuadran I",IF(AND(C16<1,J16>0),"Kuadran II",IF(AND(C16>=1,J16<=0),"Kuadran III","Kuadran IV"))) -> Kuadran III | J16: =SSA!N22 -> -182.04569
A17: =PDRB!A16 -> L | B17: =PDRB!B16 -> Real Estate | C17: =LQ!I18 -> 1.6863453 | D17: =IF(C17>=1,"LQ ≥ 1 (basis)","LQ < 1 (non-basis)") -> LQ ≥ 1 (basis) | E17: =SSA!L23 -> 92.319884 | F17: =IF(E17>0,"SSA (+)","SSA (−)") -> SSA (+) | G17: =IF(AND(C17>=1,E17>0),"Kuadran I",IF(AND(C17<1,E17>0),"Kuadran II",IF(AND(C17>=1,E17<=0),"Kuadran III","Kuadran IV"))) -> Kuadran I | H17: =IF(G17="Kuadran I","Maju dan tumbuh cepat",IF(G17="Kuadran II","Potensial / berkembang cepat",IF(G17="Kuadran III","Maju tapi tertekan","Relatif tertinggal"))) -> Maju dan tumbuh cepat | I17: =IF(AND(C17>=1,J17>0),"Kuadran I",IF(AND(C17<1,J17>0),"Kuadran II",IF(AND(C17>=1,J17<=0),"Kuadran III","Kuadran IV"))) -> Kuadran III | J17: =SSA!N23 -> -33.906152
... A22: =PDRB!A21 -> R,S,T, U | B22: =PDRB!B21 -> Jasa lainnya | C22: =LQ!I23 -> 1.6310549 | D22: =IF(C22>=1,"LQ ≥ 1 (basis)","LQ < 1 (non-basis)") -> LQ ≥ 1 (basis) | E22: =SSA!L28 -> 184.19807 | F22: =IF(E22>0,"SSA (+)","SSA (−)") -> SSA (+) | G22: =IF(AND(C22>=1,E22>0),"Kuadran I",IF(AND(C22<1,E22>0),"Kuadran II",IF(AND(C22>=1,E22<=0),"Kuadran III","Kuadran IV"))) -> Kuadran I | H22: =IF(G22="Kuadran I","Maju dan tumbuh cepat",IF(G22="Kuadran II","Potensial / berkembang cepat",IF(G22="Kuadran III","Maju tapi tertekan","Relatif tertinggal"))) -> Maju dan tumbuh cepat | I22: =IF(AND(C22>=1,J22>0),"Kuadran I",IF(AND(C22<1,J22>0),"Kuadran II",IF(AND(C22>=1,J22<=0),"Kuadran III","Kuadran IV"))) -> Kuadran I | J22: =SSA!N28 -> 94.434527
A25: MATRIKS TIPOLOGI SEKTOR (jumlah sektor)
B26: SSA Negatif (−) | C26: SSA Positif (+)
A27: LQ ≥ 1 | B27: =COUNTIF($G$6:$G$22,"Kuadran III") -> 6 | C27: =COUNTIF($G$6:$G$22,"Kuadran I") -> 8 | D27: Kuadran III = maju tapi tertekan | Kuadran I = maju dan tumbuh cepat
A28: LQ < 1 | B28: =COUNTIF($G$6:$G$22,"Kuadran IV") -> 3 | C28: =COUNTIF($G$6:$G$22,"Kuadran II") -> 0 | D28: Kuadran IV = relatif tertinggal | Kuadran II = potensial / berkembang cepat
A30: Catatan: Gambar 3 pada panduan yang diunggah menempatkan Kuadran II pada (LQ>1, SSA−) dan Kuadran III pada (LQ<1, SSA+),
A31: sedangkan uraian kriteria di bawah gambar tersebut menyatakan sebaliknya. Yang dipakai di sini adalah versi uraian kriteria (juga versi baku literatur),
A32: karena label "maju tapi tertekan" hanya konsisten dengan LQ ≥ 1 (maju/basis) dan SSA negatif (tertekan). Rumus di kolom G dapat diubah bila diperlukan.

Sheet Metodologi
A1: METODOLOGI, NOTASI, DAN CONTOH PERHITUNGAN MANUAL
A3: A. LOCATION QUOTIENT (LQ)
A4: Rumus | E4: LQ = (Xij / RVj) ÷ (Xi / RVi)
A5: Xij | E5: PDRB sektor i pada Kota Bogor
A6: RVj | E6: Total PDRB Kota Bogor
A7: Xi | E7: PDRB sektor i Provinsi Jawa Barat
A8: RVi | E8: Total PDRB Provinsi Jawa Barat
A9: Interpretasi | E9: LQ > 1 → sektor basis (spesialisasi, mampu melayani luar daerah); LQ < 1 → non-basis
A11: B. SHIFT SHARE (SS)
A12: Rumus | E12: Dij = Nij + Mij + Cij
A13: Nij = Yij × rn | E13: Pengaruh pertumbuhan ekonomi referensi (provincial share)
A14: Mij = Yij × (rin − rn) | E14: Pergeseran proporsional / bauran industri (proportional shift)
A15: Cij = Yij × (rij − rn) | E15: Pengaruh keunggulan kompetitif — sesuai dokumen yang diunggah
A16: Yij | E16: PDRB sektor i Kota Bogor pada tahun awal (t₀ = 2019)
A17: rij | E17: (Yij t − Yij t₀) / Yij t₀ — laju pertumbuhan sektor i Kota Bogor
A18: rin | E18: (Yin t − Yin t₀) / Yin t₀ — laju pertumbuhan sektor i Jawa Barat
A19: rn | E19: (Yn t − Yn t₀) / Yn t₀ — laju pertumbuhan total PDRB Jawa Barat
A20: Wilayah referensi | E20: Jawa Barat (data nasional tidak tersedia pada berkas). Notasi "n" dibaca = Jawa Barat.
A22: C. TIPOLOGI SEKTOR (LQ × SSA)
A23: Kuadran I | E23: LQ ≥ 1 dan SSA (+) → sektor maju dan tumbuh cepat (high growth, high income)
A24: Kuadran II | E24: LQ < 1 dan SSA (+) → sektor potensial / berkembang cepat (high growth, low income)
A25: Kuadran III | E25: LQ ≥ 1 dan SSA (−) → sektor maju tapi tertekan (low growth, high income)
A26: Kuadran IV | E26: LQ < 1 dan SSA (−) → sektor relatif tertinggal (low growth, low income)
A28: D. CONTOH PERHITUNGAN MANUAL — sektor H (Transportasi dan Pergudangan), 2019 → 2024
A29: Langkah | B29: Nilai | C29: Formula sel | E29: Keterangan
A30: Xij = PDRB sektor H Kota Bogor 2019 | B30: =PDRB!I12 -> 3933.69 | C30: PDRB!I12 | E30: Miliar Rp
A31: RVj = Total PDRB Kota Bogor 2019 | B31: =PDRB!I22 -> 32295.74 | C31: PDRB!I22 | E31: Miliar Rp
A32: Xi = PDRB sektor H Jawa Barat 2019 | B32: =PDRB!C12 -> 71064.36 | C32: PDRB!C12 | E32: Miliar Rp
A33: RVi = Total PDRB Jawa Barat 2019 | B33: =PDRB!C22 -> 1490959.7 | C33: PDRB!C22 | E33: Miliar Rp
A34: Pangsa sektor H di Kota Bogor = Xij/RVj | B34: =B30/B31 -> 0.12180213 | C34: B30/B31 | E34: Share lokal
A35: Pangsa sektor H di Jawa Barat = Xi/RVi | B35: =B32/B33 -> 0.047663502 | C35: B32/B33 | E35: Share referensi
A36: LQ 2019 = (Xij/RVj)/(Xi/RVi) | B36: =B34/B35 -> 2.5554592 | C36: B34/B35 | E36: Bandingkan dengan sel LQ!C14
A37: Yij (2019) | B37: =PDRB!I12 -> 3933.69 | C37: PDRB!I12 | E37: Basis perhitungan shift share
A38: Yij (2024) | B38: =PDRB!N12 -> 5322.75 | C38: PDRB!N12
A39: rij = (Yij2024 − Yij2019)/Yij2019 | B39: =(B38-B37)/B37 -> 0.35311883 | C39: (B38-B37)/B37 | E39: Pertumbuhan sektor H Kota Bogor
A40: rin = (Yin2024 − Yin2019)/Yin2019 | B40: =(PDRB!H12-PDRB!C12)/PDRB!C12 -> 0.32434725 | C40: (PDRB!H12-PDRB!C12)/PDRB!C12 | E40: Pertumbuhan sektor H Jawa Barat
A41: rn = (Yn2024 − Yn2019)/Yn2019 | B41: =(PDRB!H22-PDRB!C22)/PDRB!C22 -> 0.17512982 | C41: (PDRB!H22-PDRB!C22)/PDRB!C22 | E41: Pertumbuhan total PDRB Jawa Barat
A42: Nij = Yij × rn | B42: =B37*B41 -> 688.90641 | C42: B37*B41 | E42: Efek pertumbuhan wilayah referensi
A43: Mij = Yij × (rin − rn) | B43: =B37*(B40-B41) -> 586.97514 | C43: B37*(B40-B41) | E43: Efek bauran industri
A44: Cij = Yij × (rij − rn) [versi panduan] | B44: =B37*(B39-B41) -> 700.15359 | C44: B37*(B39-B41) | E44: Bandingkan dengan sel SSA!L19
...
